<testsuite errors="65" failures="0" name="Django Project Tests" skips="0" tests="7" time="0.224"><testcase classname="unittest.suite._ErrorHolder" name="setUpClass (treasurer_tools.bank_transactions.tests.test_forms.BankTransactionFormTest)" time="0.011020"><error message="No fixture named 'institution' found." type="django.core.management.base.CommandError">Traceback (most recent call last):
  File "C:\Program Files (x86)\Python36\lib\site-packages\django\test\testcases.py", line 1036, in setUpClass
    'database': db_name,
  File "C:\Program Files (x86)\Python36\lib\site-packages\django\core\management\__init__.py", line 131, in call_command
    return command.execute(*args, **defaults)
  File "C:\Program Files (x86)\Python36\lib\site-packages\django\core\management\base.py", line 330, in execute
    output = self.handle(*args, **options)
  File "C:\Program Files (x86)\Python36\lib\site-packages\django\core\management\commands\loaddata.py", line 69, in handle
    self.loaddata(fixture_labels)
  File "C:\Program Files (x86)\Python36\lib\site-packages\django\core\management\commands\loaddata.py", line 102, in loaddata
    if self.find_fixtures(fixture_label):
  File "C:\Program Files (x86)\Python36\lib\site-packages\django\core\management\commands\loaddata.py", line 261, in find_fixtures
    raise CommandError("No fixture named '%s' found." % fixture_name)
django.core.management.base.CommandError: No fixture named 'institution' found.
</error></testcase><testcase classname="unittest.suite._ErrorHolder" name="setUpClass (treasurer_tools.bank_transactions.tests.test_forms.StatementFormTest)" time="0.023542"><error message="No fixture named 'institution' found." type="django.core.management.base.CommandError">Traceback (most recent call last):
  File "C:\Program Files (x86)\Python36\lib\site-packages\django\test\testcases.py", line 1036, in setUpClass
    'database': db_name,
  File "C:\Program Files (x86)\Python36\lib\site-packages\django\core\management\__init__.py", line 131, in call_command
    return command.execute(*args, **defaults)
  File "C:\Program Files (x86)\Python36\lib\site-packages\django\core\management\base.py", line 330, in execute
    output = self.handle(*args, **options)
  File "C:\Program Files (x86)\Python36\lib\site-packages\django\core\management\commands\loaddata.py", line 69, in handle
    self.loaddata(fixture_labels)
  File "C:\Program Files (x86)\Python36\lib\site-packages\django\core\management\commands\loaddata.py", line 102, in loaddata
    if self.find_fixtures(fixture_label):
  File "C:\Program Files (x86)\Python36\lib\site-packages\django\core\management\commands\loaddata.py", line 261, in find_fixtures
    raise CommandError("No fixture named '%s' found." % fixture_name)
django.core.management.base.CommandError: No fixture named 'institution' found.
</error></testcase><testcase classname="unittest.suite._ErrorHolder" name="setUpClass (treasurer_tools.bank_transactions.tests.test_models.AccountModelTest)" time="0.025045"><error message="No fixture named 'institution' found." type="django.core.management.base.CommandError">Traceback (most recent call last):
  File "C:\Program Files (x86)\Python36\lib\site-packages\django\test\testcases.py", line 1036, in setUpClass
    'database': db_name,
  File "C:\Program Files (x86)\Python36\lib\site-packages\django\core\management\__init__.py", line 131, in call_command
    return command.execute(*args, **defaults)
  File "C:\Program Files (x86)\Python36\lib\site-packages\django\core\management\base.py", line 330, in execute
    output = self.handle(*args, **options)
  File "C:\Program Files (x86)\Python36\lib\site-packages\django\core\management\commands\loaddata.py", line 69, in handle
    self.loaddata(fixture_labels)
  File "C:\Program Files (x86)\Python36\lib\site-packages\django\core\management\commands\loaddata.py", line 102, in loaddata
    if self.find_fixtures(fixture_label):
  File "C:\Program Files (x86)\Python36\lib\site-packages\django\core\management\commands\loaddata.py", line 261, in find_fixtures
    raise CommandError("No fixture named '%s' found." % fixture_name)
django.core.management.base.CommandError: No fixture named 'institution' found.
</error></testcase><testcase classname="unittest.suite._ErrorHolder" name="setUpClass (treasurer_tools.bank_transactions.tests.test_models.AttachmentMatchModelTest)" time="0.026047"><error message="No fixture named 'attachment' found." type="django.core.management.base.CommandError">Traceback (most recent call last):
  File "C:\Program Files (x86)\Python36\lib\site-packages\django\test\testcases.py", line 1036, in setUpClass
    'database': db_name,
  File "C:\Program Files (x86)\Python36\lib\site-packages\django\core\management\__init__.py", line 131, in call_command
    return command.execute(*args, **defaults)
  File "C:\Program Files (x86)\Python36\lib\site-packages\django\core\management\base.py", line 330, in execute
    output = self.handle(*args, **options)
  File "C:\Program Files (x86)\Python36\lib\site-packages\django\core\management\commands\loaddata.py", line 69, in handle
    self.loaddata(fixture_labels)
  File "C:\Program Files (x86)\Python36\lib\site-packages\django\core\management\commands\loaddata.py", line 102, in loaddata
    if self.find_fixtures(fixture_label):
  File "C:\Program Files (x86)\Python36\lib\site-packages\django\core\management\commands\loaddata.py", line 261, in find_fixtures
    raise CommandError("No fixture named '%s' found." % fixture_name)
django.core.management.base.CommandError: No fixture named 'attachment' found.
</error></testcase><testcase classname="unittest.suite._ErrorHolder" name="setUpClass (treasurer_tools.bank_transactions.tests.test_models.BankTransactionModelTest)" time="0.027549"><error message="No fixture named 'institution' found." type="django.core.management.base.CommandError">Traceback (most recent call last):
  File "C:\Program Files (x86)\Python36\lib\site-packages\django\test\testcases.py", line 1036, in setUpClass
    'database': db_name,
  File "C:\Program Files (x86)\Python36\lib\site-packages\django\core\management\__init__.py", line 131, in call_command
    return command.execute(*args, **defaults)
  File "C:\Program Files (x86)\Python36\lib\site-packages\django\core\management\base.py", line 330, in execute
    output = self.handle(*args, **options)
  File "C:\Program Files (x86)\Python36\lib\site-packages\django\core\management\commands\loaddata.py", line 69, in handle
    self.loaddata(fixture_labels)
  File "C:\Program Files (x86)\Python36\lib\site-packages\django\core\management\commands\loaddata.py", line 102, in loaddata
    if self.find_fixtures(fixture_label):
  File "C:\Program Files (x86)\Python36\lib\site-packages\django\core\management\commands\loaddata.py", line 261, in find_fixtures
    raise CommandError("No fixture named '%s' found." % fixture_name)
django.core.management.base.CommandError: No fixture named 'institution' found.
</error></testcase><testcase classname="unittest.suite._ErrorHolder" name="setUpClass (treasurer_tools.bank_transactions.tests.test_models.InstitutionModelTest)" time="0.028551"><error message="No fixture named 'institution' found." type="django.core.management.base.CommandError">Traceback (most recent call last):
  File "C:\Program Files (x86)\Python36\lib\site-packages\django\test\testcases.py", line 1036, in setUpClass
    'database': db_name,
  File "C:\Program Files (x86)\Python36\lib\site-packages\django\core\management\__init__.py", line 131, in call_command
    return command.execute(*args, **defaults)
  File "C:\Program Files (x86)\Python36\lib\site-packages\django\core\management\base.py", line 330, in execute
    output = self.handle(*args, **options)
  File "C:\Program Files (x86)\Python36\lib\site-packages\django\core\management\commands\loaddata.py", line 69, in handle
    self.loaddata(fixture_labels)
  File "C:\Program Files (x86)\Python36\lib\site-packages\django\core\management\commands\loaddata.py", line 102, in loaddata
    if self.find_fixtures(fixture_label):
  File "C:\Program Files (x86)\Python36\lib\site-packages\django\core\management\commands\loaddata.py", line 261, in find_fixtures
    raise CommandError("No fixture named '%s' found." % fixture_name)
django.core.management.base.CommandError: No fixture named 'institution' found.
</error></testcase><testcase classname="unittest.suite._ErrorHolder" name="setUpClass (treasurer_tools.bank_transactions.tests.test_models.StatementModelTest)" time="0.030054"><error message="No fixture named 'institution' found." type="django.core.management.base.CommandError">Traceback (most recent call last):
  File "C:\Program Files (x86)\Python36\lib\site-packages\django\test\testcases.py", line 1036, in setUpClass
    'database': db_name,
  File "C:\Program Files (x86)\Python36\lib\site-packages\django\core\management\__init__.py", line 131, in call_command
    return command.execute(*args, **defaults)
  File "C:\Program Files (x86)\Python36\lib\site-packages\django\core\management\base.py", line 330, in execute
    output = self.handle(*args, **options)
  File "C:\Program Files (x86)\Python36\lib\site-packages\django\core\management\commands\loaddata.py", line 69, in handle
    self.loaddata(fixture_labels)
  File "C:\Program Files (x86)\Python36\lib\site-packages\django\core\management\commands\loaddata.py", line 102, in loaddata
    if self.find_fixtures(fixture_label):
  File "C:\Program Files (x86)\Python36\lib\site-packages\django\core\management\commands\loaddata.py", line 261, in find_fixtures
    raise CommandError("No fixture named '%s' found." % fixture_name)
django.core.management.base.CommandError: No fixture named 'institution' found.
</error></testcase><testcase classname="unittest.suite._ErrorHolder" name="setUpClass (treasurer_tools.bank_transactions.tests.test_views.BankDashboardTest)" time="0.031556"><error message="No fixture named 'authentication' found." type="django.core.management.base.CommandError">Traceback (most recent call last):
  File "C:\Program Files (x86)\Python36\lib\site-packages\django\test\testcases.py", line 1036, in setUpClass
    'database': db_name,
  File "C:\Program Files (x86)\Python36\lib\site-packages\django\core\management\__init__.py", line 131, in call_command
    return command.execute(*args, **defaults)
  File "C:\Program Files (x86)\Python36\lib\site-packages\django\core\management\base.py", line 330, in execute
    output = self.handle(*args, **options)
  File "C:\Program Files (x86)\Python36\lib\site-packages\django\core\management\commands\loaddata.py", line 69, in handle
    self.loaddata(fixture_labels)
  File "C:\Program Files (x86)\Python36\lib\site-packages\django\core\management\commands\loaddata.py", line 102, in loaddata
    if self.find_fixtures(fixture_label):
  File "C:\Program Files (x86)\Python36\lib\site-packages\django\core\management\commands\loaddata.py", line 261, in find_fixtures
    raise CommandError("No fixture named '%s' found." % fixture_name)
django.core.management.base.CommandError: No fixture named 'authentication' found.
</error></testcase><testcase classname="unittest.suite._ErrorHolder" name="setUpClass (treasurer_tools.bank_transactions.tests.test_views.StatementAddTest)" time="0.032558"><error message="No fixture named 'authentication' found." type="django.core.management.base.CommandError">Traceback (most recent call last):
  File "C:\Program Files (x86)\Python36\lib\site-packages\django\test\testcases.py", line 1036, in setUpClass
    'database': db_name,
  File "C:\Program Files (x86)\Python36\lib\site-packages\django\core\management\__init__.py", line 131, in call_command
    return command.execute(*args, **defaults)
  File "C:\Program Files (x86)\Python36\lib\site-packages\django\core\management\base.py", line 330, in execute
    output = self.handle(*args, **options)
  File "C:\Program Files (x86)\Python36\lib\site-packages\django\core\management\commands\loaddata.py", line 69, in handle
    self.loaddata(fixture_labels)
  File "C:\Program Files (x86)\Python36\lib\site-packages\django\core\management\commands\loaddata.py", line 102, in loaddata
    if self.find_fixtures(fixture_label):
  File "C:\Program Files (x86)\Python36\lib\site-packages\django\core\management\commands\loaddata.py", line 261, in find_fixtures
    raise CommandError("No fixture named '%s' found." % fixture_name)
django.core.management.base.CommandError: No fixture named 'authentication' found.
</error></testcase><testcase classname="unittest.suite._ErrorHolder" name="setUpClass (treasurer_tools.bank_transactions.tests.test_views.StatementDeleteTest)" time="0.034061"><error message="No fixture named 'authentication' found." type="django.core.management.base.CommandError">Traceback (most recent call last):
  File "C:\Program Files (x86)\Python36\lib\site-packages\django\test\testcases.py", line 1036, in setUpClass
    'database': db_name,
  File "C:\Program Files (x86)\Python36\lib\site-packages\django\core\management\__init__.py", line 131, in call_command
    return command.execute(*args, **defaults)
  File "C:\Program Files (x86)\Python36\lib\site-packages\django\core\management\base.py", line 330, in execute
    output = self.handle(*args, **options)
  File "C:\Program Files (x86)\Python36\lib\site-packages\django\core\management\commands\loaddata.py", line 69, in handle
    self.loaddata(fixture_labels)
  File "C:\Program Files (x86)\Python36\lib\site-packages\django\core\management\commands\loaddata.py", line 102, in loaddata
    if self.find_fixtures(fixture_label):
  File "C:\Program Files (x86)\Python36\lib\site-packages\django\core\management\commands\loaddata.py", line 261, in find_fixtures
    raise CommandError("No fixture named '%s' found." % fixture_name)
django.core.management.base.CommandError: No fixture named 'authentication' found.
</error></testcase><testcase classname="unittest.suite._ErrorHolder" name="setUpClass (treasurer_tools.bank_transactions.tests.test_views.StatementEditTest)" time="0.035063"><error message="No fixture named 'authentication' found." type="django.core.management.base.CommandError">Traceback (most recent call last):
  File "C:\Program Files (x86)\Python36\lib\site-packages\django\test\testcases.py", line 1036, in setUpClass
    'database': db_name,
  File "C:\Program Files (x86)\Python36\lib\site-packages\django\core\management\__init__.py", line 131, in call_command
    return command.execute(*args, **defaults)
  File "C:\Program Files (x86)\Python36\lib\site-packages\django\core\management\base.py", line 330, in execute
    output = self.handle(*args, **options)
  File "C:\Program Files (x86)\Python36\lib\site-packages\django\core\management\commands\loaddata.py", line 69, in handle
    self.loaddata(fixture_labels)
  File "C:\Program Files (x86)\Python36\lib\site-packages\django\core\management\commands\loaddata.py", line 102, in loaddata
    if self.find_fixtures(fixture_label):
  File "C:\Program Files (x86)\Python36\lib\site-packages\django\core\management\commands\loaddata.py", line 261, in find_fixtures
    raise CommandError("No fixture named '%s' found." % fixture_name)
django.core.management.base.CommandError: No fixture named 'authentication' found.
</error></testcase><testcase classname="unittest.suite._ErrorHolder" name="setUpClass (treasurer_tools.bank_transactions.tests.test_views_settings.BankSettingsTest)" time="0.036565"><error message="No fixture named 'authentication' found." type="django.core.management.base.CommandError">Traceback (most recent call last):
  File "C:\Program Files (x86)\Python36\lib\site-packages\django\test\testcases.py", line 1036, in setUpClass
    'database': db_name,
  File "C:\Program Files (x86)\Python36\lib\site-packages\django\core\management\__init__.py", line 131, in call_command
    return command.execute(*args, **defaults)
  File "C:\Program Files (x86)\Python36\lib\site-packages\django\core\management\base.py", line 330, in execute
    output = self.handle(*args, **options)
  File "C:\Program Files (x86)\Python36\lib\site-packages\django\core\management\commands\loaddata.py", line 69, in handle
    self.loaddata(fixture_labels)
  File "C:\Program Files (x86)\Python36\lib\site-packages\django\core\management\commands\loaddata.py", line 102, in loaddata
    if self.find_fixtures(fixture_label):
  File "C:\Program Files (x86)\Python36\lib\site-packages\django\core\management\commands\loaddata.py", line 261, in find_fixtures
    raise CommandError("No fixture named '%s' found." % fixture_name)
django.core.management.base.CommandError: No fixture named 'authentication' found.
</error></testcase><testcase classname="unittest.suite._ErrorHolder" name="setUpClass (treasurer_tools.bank_transactions.tests.test_views_settings.InstitutionAddTest)" time="0.037567"><error message="No fixture named 'authentication' found." type="django.core.management.base.CommandError">Traceback (most recent call last):
  File "C:\Program Files (x86)\Python36\lib\site-packages\django\test\testcases.py", line 1036, in setUpClass
    'database': db_name,
  File "C:\Program Files (x86)\Python36\lib\site-packages\django\core\management\__init__.py", line 131, in call_command
    return command.execute(*args, **defaults)
  File "C:\Program Files (x86)\Python36\lib\site-packages\django\core\management\base.py", line 330, in execute
    output = self.handle(*args, **options)
  File "C:\Program Files (x86)\Python36\lib\site-packages\django\core\management\commands\loaddata.py", line 69, in handle
    self.loaddata(fixture_labels)
  File "C:\Program Files (x86)\Python36\lib\site-packages\django\core\management\commands\loaddata.py", line 102, in loaddata
    if self.find_fixtures(fixture_label):
  File "C:\Program Files (x86)\Python36\lib\site-packages\django\core\management\commands\loaddata.py", line 261, in find_fixtures
    raise CommandError("No fixture named '%s' found." % fixture_name)
django.core.management.base.CommandError: No fixture named 'authentication' found.
</error></testcase><testcase classname="unittest.suite._ErrorHolder" name="setUpClass (treasurer_tools.bank_transactions.tests.test_views_settings.InstitutionDeleteTest)" time="0.039069"><error message="No fixture named 'authentication' found." type="django.core.management.base.CommandError">Traceback (most recent call last):
  File "C:\Program Files (x86)\Python36\lib\site-packages\django\test\testcases.py", line 1036, in setUpClass
    'database': db_name,
  File "C:\Program Files (x86)\Python36\lib\site-packages\django\core\management\__init__.py", line 131, in call_command
    return command.execute(*args, **defaults)
  File "C:\Program Files (x86)\Python36\lib\site-packages\django\core\management\base.py", line 330, in execute
    output = self.handle(*args, **options)
  File "C:\Program Files (x86)\Python36\lib\site-packages\django\core\management\commands\loaddata.py", line 69, in handle
    self.loaddata(fixture_labels)
  File "C:\Program Files (x86)\Python36\lib\site-packages\django\core\management\commands\loaddata.py", line 102, in loaddata
    if self.find_fixtures(fixture_label):
  File "C:\Program Files (x86)\Python36\lib\site-packages\django\core\management\commands\loaddata.py", line 261, in find_fixtures
    raise CommandError("No fixture named '%s' found." % fixture_name)
django.core.management.base.CommandError: No fixture named 'authentication' found.
</error></testcase><testcase classname="unittest.suite._ErrorHolder" name="setUpClass (treasurer_tools.bank_transactions.tests.test_views_settings.InstitutionEditTest)" time="0.040071"><error message="No fixture named 'authentication' found." type="django.core.management.base.CommandError">Traceback (most recent call last):
  File "C:\Program Files (x86)\Python36\lib\site-packages\django\test\testcases.py", line 1036, in setUpClass
    'database': db_name,
  File "C:\Program Files (x86)\Python36\lib\site-packages\django\core\management\__init__.py", line 131, in call_command
    return command.execute(*args, **defaults)
  File "C:\Program Files (x86)\Python36\lib\site-packages\django\core\management\base.py", line 330, in execute
    output = self.handle(*args, **options)
  File "C:\Program Files (x86)\Python36\lib\site-packages\django\core\management\commands\loaddata.py", line 69, in handle
    self.loaddata(fixture_labels)
  File "C:\Program Files (x86)\Python36\lib\site-packages\django\core\management\commands\loaddata.py", line 102, in loaddata
    if self.find_fixtures(fixture_label):
  File "C:\Program Files (x86)\Python36\lib\site-packages\django\core\management\commands\loaddata.py", line 261, in find_fixtures
    raise CommandError("No fixture named '%s' found." % fixture_name)
django.core.management.base.CommandError: No fixture named 'authentication' found.
</error></testcase><testcase classname="unittest.suite._ErrorHolder" name="setUpClass (treasurer_tools.documents.tests.test_models.AttachmentModelTest)" time="0.041574"><error message="No fixture named 'attachment' found." type="django.core.management.base.CommandError">Traceback (most recent call last):
  File "C:\Program Files (x86)\Python36\lib\site-packages\django\test\testcases.py", line 1036, in setUpClass
    'database': db_name,
  File "C:\Program Files (x86)\Python36\lib\site-packages\django\core\management\__init__.py", line 131, in call_command
    return command.execute(*args, **defaults)
  File "C:\Program Files (x86)\Python36\lib\site-packages\django\core\management\base.py", line 330, in execute
    output = self.handle(*args, **options)
  File "C:\Program Files (x86)\Python36\lib\site-packages\django\core\management\commands\loaddata.py", line 69, in handle
    self.loaddata(fixture_labels)
  File "C:\Program Files (x86)\Python36\lib\site-packages\django\core\management\commands\loaddata.py", line 102, in loaddata
    if self.find_fixtures(fixture_label):
  File "C:\Program Files (x86)\Python36\lib\site-packages\django\core\management\commands\loaddata.py", line 261, in find_fixtures
    raise CommandError("No fixture named '%s' found." % fixture_name)
django.core.management.base.CommandError: No fixture named 'attachment' found.
</error></testcase><testcase classname="unittest.suite._ErrorHolder" name="setUpClass (treasurer_tools.financial_codes.tests.test_models.BudgetYearModelTest)" time="0.042576"><error message="No fixture named 'financial_code_system' found." type="django.core.management.base.CommandError">Traceback (most recent call last):
  File "C:\Program Files (x86)\Python36\lib\site-packages\django\test\testcases.py", line 1036, in setUpClass
    'database': db_name,
  File "C:\Program Files (x86)\Python36\lib\site-packages\django\core\management\__init__.py", line 131, in call_command
    return command.execute(*args, **defaults)
  File "C:\Program Files (x86)\Python36\lib\site-packages\django\core\management\base.py", line 330, in execute
    output = self.handle(*args, **options)
  File "C:\Program Files (x86)\Python36\lib\site-packages\django\core\management\commands\loaddata.py", line 69, in handle
    self.loaddata(fixture_labels)
  File "C:\Program Files (x86)\Python36\lib\site-packages\django\core\management\commands\loaddata.py", line 102, in loaddata
    if self.find_fixtures(fixture_label):
  File "C:\Program Files (x86)\Python36\lib\site-packages\django\core\management\commands\loaddata.py", line 261, in find_fixtures
    raise CommandError("No fixture named '%s' found." % fixture_name)
django.core.management.base.CommandError: No fixture named 'financial_code_system' found.
</error></testcase><testcase classname="unittest.suite._ErrorHolder" name="setUpClass (treasurer_tools.financial_codes.tests.test_models.FinancialCodeGroupModelTest)" time="0.044079"><error message="No fixture named 'financial_code_system' found." type="django.core.management.base.CommandError">Traceback (most recent call last):
  File "C:\Program Files (x86)\Python36\lib\site-packages\django\test\testcases.py", line 1036, in setUpClass
    'database': db_name,
  File "C:\Program Files (x86)\Python36\lib\site-packages\django\core\management\__init__.py", line 131, in call_command
    return command.execute(*args, **defaults)
  File "C:\Program Files (x86)\Python36\lib\site-packages\django\core\management\base.py", line 330, in execute
    output = self.handle(*args, **options)
  File "C:\Program Files (x86)\Python36\lib\site-packages\django\core\management\commands\loaddata.py", line 69, in handle
    self.loaddata(fixture_labels)
  File "C:\Program Files (x86)\Python36\lib\site-packages\django\core\management\commands\loaddata.py", line 102, in loaddata
    if self.find_fixtures(fixture_label):
  File "C:\Program Files (x86)\Python36\lib\site-packages\django\core\management\commands\loaddata.py", line 261, in find_fixtures
    raise CommandError("No fixture named '%s' found." % fixture_name)
django.core.management.base.CommandError: No fixture named 'financial_code_system' found.
</error></testcase><testcase classname="unittest.suite._ErrorHolder" name="setUpClass (treasurer_tools.financial_codes.tests.test_models.FinancialCodeModelTest)" time="0.045080"><error message="No fixture named 'financial_code_system' found." type="django.core.management.base.CommandError">Traceback (most recent call last):
  File "C:\Program Files (x86)\Python36\lib\site-packages\django\test\testcases.py", line 1036, in setUpClass
    'database': db_name,
  File "C:\Program Files (x86)\Python36\lib\site-packages\django\core\management\__init__.py", line 131, in call_command
    return command.execute(*args, **defaults)
  File "C:\Program Files (x86)\Python36\lib\site-packages\django\core\management\base.py", line 330, in execute
    output = self.handle(*args, **options)
  File "C:\Program Files (x86)\Python36\lib\site-packages\django\core\management\commands\loaddata.py", line 69, in handle
    self.loaddata(fixture_labels)
  File "C:\Program Files (x86)\Python36\lib\site-packages\django\core\management\commands\loaddata.py", line 102, in loaddata
    if self.find_fixtures(fixture_label):
  File "C:\Program Files (x86)\Python36\lib\site-packages\django\core\management\commands\loaddata.py", line 261, in find_fixtures
    raise CommandError("No fixture named '%s' found." % fixture_name)
django.core.management.base.CommandError: No fixture named 'financial_code_system' found.
</error></testcase><testcase classname="unittest.suite._ErrorHolder" name="setUpClass (treasurer_tools.financial_codes.tests.test_models.FinancialCodeSystemModelTest)" time="0.046583"><error message="No fixture named 'financial_code_system' found." type="django.core.management.base.CommandError">Traceback (most recent call last):
  File "C:\Program Files (x86)\Python36\lib\site-packages\django\test\testcases.py", line 1036, in setUpClass
    'database': db_name,
  File "C:\Program Files (x86)\Python36\lib\site-packages\django\core\management\__init__.py", line 131, in call_command
    return command.execute(*args, **defaults)
  File "C:\Program Files (x86)\Python36\lib\site-packages\django\core\management\base.py", line 330, in execute
    output = self.handle(*args, **options)
  File "C:\Program Files (x86)\Python36\lib\site-packages\django\core\management\commands\loaddata.py", line 69, in handle
    self.loaddata(fixture_labels)
  File "C:\Program Files (x86)\Python36\lib\site-packages\django\core\management\commands\loaddata.py", line 102, in loaddata
    if self.find_fixtures(fixture_label):
  File "C:\Program Files (x86)\Python36\lib\site-packages\django\core\management\commands\loaddata.py", line 261, in find_fixtures
    raise CommandError("No fixture named '%s' found." % fixture_name)
django.core.management.base.CommandError: No fixture named 'financial_code_system' found.
</error></testcase><testcase classname="unittest.suite._ErrorHolder" name="setUpClass (treasurer_tools.financial_codes.tests.test_views.FinancialCodeDashboard)" time="0.047585"><error message="No fixture named 'authentication' found." type="django.core.management.base.CommandError">Traceback (most recent call last):
  File "C:\Program Files (x86)\Python36\lib\site-packages\django\test\testcases.py", line 1036, in setUpClass
    'database': db_name,
  File "C:\Program Files (x86)\Python36\lib\site-packages\django\core\management\__init__.py", line 131, in call_command
    return command.execute(*args, **defaults)
  File "C:\Program Files (x86)\Python36\lib\site-packages\django\core\management\base.py", line 330, in execute
    output = self.handle(*args, **options)
  File "C:\Program Files (x86)\Python36\lib\site-packages\django\core\management\commands\loaddata.py", line 69, in handle
    self.loaddata(fixture_labels)
  File "C:\Program Files (x86)\Python36\lib\site-packages\django\core\management\commands\loaddata.py", line 102, in loaddata
    if self.find_fixtures(fixture_label):
  File "C:\Program Files (x86)\Python36\lib\site-packages\django\core\management\commands\loaddata.py", line 261, in find_fixtures
    raise CommandError("No fixture named '%s' found." % fixture_name)
django.core.management.base.CommandError: No fixture named 'authentication' found.
</error></testcase><testcase classname="unittest.suite._ErrorHolder" name="setUpClass (treasurer_tools.financial_codes.tests.test_views_budget_year.BudgetYearAddTest)" time="0.049087"><error message="No fixture named 'authentication' found." type="django.core.management.base.CommandError">Traceback (most recent call last):
  File "C:\Program Files (x86)\Python36\lib\site-packages\django\test\testcases.py", line 1036, in setUpClass
    'database': db_name,
  File "C:\Program Files (x86)\Python36\lib\site-packages\django\core\management\__init__.py", line 131, in call_command
    return command.execute(*args, **defaults)
  File "C:\Program Files (x86)\Python36\lib\site-packages\django\core\management\base.py", line 330, in execute
    output = self.handle(*args, **options)
  File "C:\Program Files (x86)\Python36\lib\site-packages\django\core\management\commands\loaddata.py", line 69, in handle
    self.loaddata(fixture_labels)
  File "C:\Program Files (x86)\Python36\lib\site-packages\django\core\management\commands\loaddata.py", line 102, in loaddata
    if self.find_fixtures(fixture_label):
  File "C:\Program Files (x86)\Python36\lib\site-packages\django\core\management\commands\loaddata.py", line 261, in find_fixtures
    raise CommandError("No fixture named '%s' found." % fixture_name)
django.core.management.base.CommandError: No fixture named 'authentication' found.
</error></testcase><testcase classname="unittest.suite._ErrorHolder" name="setUpClass (treasurer_tools.financial_codes.tests.test_views_budget_year.BudgetYearDeleteTest)" time="0.050089"><error message="No fixture named 'authentication' found." type="django.core.management.base.CommandError">Traceback (most recent call last):
  File "C:\Program Files (x86)\Python36\lib\site-packages\django\test\testcases.py", line 1036, in setUpClass
    'database': db_name,
  File "C:\Program Files (x86)\Python36\lib\site-packages\django\core\management\__init__.py", line 131, in call_command
    return command.execute(*args, **defaults)
  File "C:\Program Files (x86)\Python36\lib\site-packages\django\core\management\base.py", line 330, in execute
    output = self.handle(*args, **options)
  File "C:\Program Files (x86)\Python36\lib\site-packages\django\core\management\commands\loaddata.py", line 69, in handle
    self.loaddata(fixture_labels)
  File "C:\Program Files (x86)\Python36\lib\site-packages\django\core\management\commands\loaddata.py", line 102, in loaddata
    if self.find_fixtures(fixture_label):
  File "C:\Program Files (x86)\Python36\lib\site-packages\django\core\management\commands\loaddata.py", line 261, in find_fixtures
    raise CommandError("No fixture named '%s' found." % fixture_name)
django.core.management.base.CommandError: No fixture named 'authentication' found.
</error></testcase><testcase classname="unittest.suite._ErrorHolder" name="setUpClass (treasurer_tools.financial_codes.tests.test_views_budget_year.BudgetYearEditTest)" time="0.051592"><error message="No fixture named 'authentication' found." type="django.core.management.base.CommandError">Traceback (most recent call last):
  File "C:\Program Files (x86)\Python36\lib\site-packages\django\test\testcases.py", line 1036, in setUpClass
    'database': db_name,
  File "C:\Program Files (x86)\Python36\lib\site-packages\django\core\management\__init__.py", line 131, in call_command
    return command.execute(*args, **defaults)
  File "C:\Program Files (x86)\Python36\lib\site-packages\django\core\management\base.py", line 330, in execute
    output = self.handle(*args, **options)
  File "C:\Program Files (x86)\Python36\lib\site-packages\django\core\management\commands\loaddata.py", line 69, in handle
    self.loaddata(fixture_labels)
  File "C:\Program Files (x86)\Python36\lib\site-packages\django\core\management\commands\loaddata.py", line 102, in loaddata
    if self.find_fixtures(fixture_label):
  File "C:\Program Files (x86)\Python36\lib\site-packages\django\core\management\commands\loaddata.py", line 261, in find_fixtures
    raise CommandError("No fixture named '%s' found." % fixture_name)
django.core.management.base.CommandError: No fixture named 'authentication' found.
</error></testcase><testcase classname="unittest.suite._ErrorHolder" name="setUpClass (treasurer_tools.financial_codes.tests.test_views_financial_code.FinancialCodeAddTest)" time="0.052593"><error message="No fixture named 'authentication' found." type="django.core.management.base.CommandError">Traceback (most recent call last):
  File "C:\Program Files (x86)\Python36\lib\site-packages\django\test\testcases.py", line 1036, in setUpClass
    'database': db_name,
  File "C:\Program Files (x86)\Python36\lib\site-packages\django\core\management\__init__.py", line 131, in call_command
    return command.execute(*args, **defaults)
  File "C:\Program Files (x86)\Python36\lib\site-packages\django\core\management\base.py", line 330, in execute
    output = self.handle(*args, **options)
  File "C:\Program Files (x86)\Python36\lib\site-packages\django\core\management\commands\loaddata.py", line 69, in handle
    self.loaddata(fixture_labels)
  File "C:\Program Files (x86)\Python36\lib\site-packages\django\core\management\commands\loaddata.py", line 102, in loaddata
    if self.find_fixtures(fixture_label):
  File "C:\Program Files (x86)\Python36\lib\site-packages\django\core\management\commands\loaddata.py", line 261, in find_fixtures
    raise CommandError("No fixture named '%s' found." % fixture_name)
django.core.management.base.CommandError: No fixture named 'authentication' found.
</error></testcase><testcase classname="unittest.suite._ErrorHolder" name="setUpClass (treasurer_tools.financial_codes.tests.test_views_financial_code.FinancialCodeDeleteTest)" time="0.054096"><error message="No fixture named 'authentication' found." type="django.core.management.base.CommandError">Traceback (most recent call last):
  File "C:\Program Files (x86)\Python36\lib\site-packages\django\test\testcases.py", line 1036, in setUpClass
    'database': db_name,
  File "C:\Program Files (x86)\Python36\lib\site-packages\django\core\management\__init__.py", line 131, in call_command
    return command.execute(*args, **defaults)
  File "C:\Program Files (x86)\Python36\lib\site-packages\django\core\management\base.py", line 330, in execute
    output = self.handle(*args, **options)
  File "C:\Program Files (x86)\Python36\lib\site-packages\django\core\management\commands\loaddata.py", line 69, in handle
    self.loaddata(fixture_labels)
  File "C:\Program Files (x86)\Python36\lib\site-packages\django\core\management\commands\loaddata.py", line 102, in loaddata
    if self.find_fixtures(fixture_label):
  File "C:\Program Files (x86)\Python36\lib\site-packages\django\core\management\commands\loaddata.py", line 261, in find_fixtures
    raise CommandError("No fixture named '%s' found." % fixture_name)
django.core.management.base.CommandError: No fixture named 'authentication' found.
</error></testcase><testcase classname="unittest.suite._ErrorHolder" name="setUpClass (treasurer_tools.financial_codes.tests.test_views_financial_code.FinancialCodeEditTest)" time="0.055098"><error message="No fixture named 'authentication' found." type="django.core.management.base.CommandError">Traceback (most recent call last):
  File "C:\Program Files (x86)\Python36\lib\site-packages\django\test\testcases.py", line 1036, in setUpClass
    'database': db_name,
  File "C:\Program Files (x86)\Python36\lib\site-packages\django\core\management\__init__.py", line 131, in call_command
    return command.execute(*args, **defaults)
  File "C:\Program Files (x86)\Python36\lib\site-packages\django\core\management\base.py", line 330, in execute
    output = self.handle(*args, **options)
  File "C:\Program Files (x86)\Python36\lib\site-packages\django\core\management\commands\loaddata.py", line 69, in handle
    self.loaddata(fixture_labels)
  File "C:\Program Files (x86)\Python36\lib\site-packages\django\core\management\commands\loaddata.py", line 102, in loaddata
    if self.find_fixtures(fixture_label):
  File "C:\Program Files (x86)\Python36\lib\site-packages\django\core\management\commands\loaddata.py", line 261, in find_fixtures
    raise CommandError("No fixture named '%s' found." % fixture_name)
django.core.management.base.CommandError: No fixture named 'authentication' found.
</error></testcase><testcase classname="unittest.suite._ErrorHolder" name="setUpClass (treasurer_tools.financial_codes.tests.test_views_financial_code_group.FinancialCodeGroupAddTest)" time="0.056601"><error message="No fixture named 'authentication' found." type="django.core.management.base.CommandError">Traceback (most recent call last):
  File "C:\Program Files (x86)\Python36\lib\site-packages\django\test\testcases.py", line 1036, in setUpClass
    'database': db_name,
  File "C:\Program Files (x86)\Python36\lib\site-packages\django\core\management\__init__.py", line 131, in call_command
    return command.execute(*args, **defaults)
  File "C:\Program Files (x86)\Python36\lib\site-packages\django\core\management\base.py", line 330, in execute
    output = self.handle(*args, **options)
  File "C:\Program Files (x86)\Python36\lib\site-packages\django\core\management\commands\loaddata.py", line 69, in handle
    self.loaddata(fixture_labels)
  File "C:\Program Files (x86)\Python36\lib\site-packages\django\core\management\commands\loaddata.py", line 102, in loaddata
    if self.find_fixtures(fixture_label):
  File "C:\Program Files (x86)\Python36\lib\site-packages\django\core\management\commands\loaddata.py", line 261, in find_fixtures
    raise CommandError("No fixture named '%s' found." % fixture_name)
django.core.management.base.CommandError: No fixture named 'authentication' found.
</error></testcase><testcase classname="unittest.suite._ErrorHolder" name="setUpClass (treasurer_tools.financial_codes.tests.test_views_financial_code_group.FinancialCodeGroupDeleteTest)" time="0.058103"><error message="No fixture named 'authentication' found." type="django.core.management.base.CommandError">Traceback (most recent call last):
  File "C:\Program Files (x86)\Python36\lib\site-packages\django\test\testcases.py", line 1036, in setUpClass
    'database': db_name,
  File "C:\Program Files (x86)\Python36\lib\site-packages\django\core\management\__init__.py", line 131, in call_command
    return command.execute(*args, **defaults)
  File "C:\Program Files (x86)\Python36\lib\site-packages\django\core\management\base.py", line 330, in execute
    output = self.handle(*args, **options)
  File "C:\Program Files (x86)\Python36\lib\site-packages\django\core\management\commands\loaddata.py", line 69, in handle
    self.loaddata(fixture_labels)
  File "C:\Program Files (x86)\Python36\lib\site-packages\django\core\management\commands\loaddata.py", line 102, in loaddata
    if self.find_fixtures(fixture_label):
  File "C:\Program Files (x86)\Python36\lib\site-packages\django\core\management\commands\loaddata.py", line 261, in find_fixtures
    raise CommandError("No fixture named '%s' found." % fixture_name)
django.core.management.base.CommandError: No fixture named 'authentication' found.
</error></testcase><testcase classname="unittest.suite._ErrorHolder" name="setUpClass (treasurer_tools.financial_codes.tests.test_views_financial_code_group.FinancialCodeGroupEditTest)" time="0.059105"><error message="No fixture named 'authentication' found." type="django.core.management.base.CommandError">Traceback (most recent call last):
  File "C:\Program Files (x86)\Python36\lib\site-packages\django\test\testcases.py", line 1036, in setUpClass
    'database': db_name,
  File "C:\Program Files (x86)\Python36\lib\site-packages\django\core\management\__init__.py", line 131, in call_command
    return command.execute(*args, **defaults)
  File "C:\Program Files (x86)\Python36\lib\site-packages\django\core\management\base.py", line 330, in execute
    output = self.handle(*args, **options)
  File "C:\Program Files (x86)\Python36\lib\site-packages\django\core\management\commands\loaddata.py", line 69, in handle
    self.loaddata(fixture_labels)
  File "C:\Program Files (x86)\Python36\lib\site-packages\django\core\management\commands\loaddata.py", line 102, in loaddata
    if self.find_fixtures(fixture_label):
  File "C:\Program Files (x86)\Python36\lib\site-packages\django\core\management\commands\loaddata.py", line 261, in find_fixtures
    raise CommandError("No fixture named '%s' found." % fixture_name)
django.core.management.base.CommandError: No fixture named 'authentication' found.
</error></testcase><testcase classname="unittest.suite._ErrorHolder" name="setUpClass (treasurer_tools.financial_codes.tests.test_views_financial_code_system.FinancialCodeSystemAddTest)" time="0.060608"><error message="No fixture named 'authentication' found." type="django.core.management.base.CommandError">Traceback (most recent call last):
  File "C:\Program Files (x86)\Python36\lib\site-packages\django\test\testcases.py", line 1036, in setUpClass
    'database': db_name,
  File "C:\Program Files (x86)\Python36\lib\site-packages\django\core\management\__init__.py", line 131, in call_command
    return command.execute(*args, **defaults)
  File "C:\Program Files (x86)\Python36\lib\site-packages\django\core\management\base.py", line 330, in execute
    output = self.handle(*args, **options)
  File "C:\Program Files (x86)\Python36\lib\site-packages\django\core\management\commands\loaddata.py", line 69, in handle
    self.loaddata(fixture_labels)
  File "C:\Program Files (x86)\Python36\lib\site-packages\django\core\management\commands\loaddata.py", line 102, in loaddata
    if self.find_fixtures(fixture_label):
  File "C:\Program Files (x86)\Python36\lib\site-packages\django\core\management\commands\loaddata.py", line 261, in find_fixtures
    raise CommandError("No fixture named '%s' found." % fixture_name)
django.core.management.base.CommandError: No fixture named 'authentication' found.
</error></testcase><testcase classname="unittest.suite._ErrorHolder" name="setUpClass (treasurer_tools.financial_codes.tests.test_views_financial_code_system.FinancialCodeSystemDeleteTest)" time="0.061610"><error message="No fixture named 'authentication' found." type="django.core.management.base.CommandError">Traceback (most recent call last):
  File "C:\Program Files (x86)\Python36\lib\site-packages\django\test\testcases.py", line 1036, in setUpClass
    'database': db_name,
  File "C:\Program Files (x86)\Python36\lib\site-packages\django\core\management\__init__.py", line 131, in call_command
    return command.execute(*args, **defaults)
  File "C:\Program Files (x86)\Python36\lib\site-packages\django\core\management\base.py", line 330, in execute
    output = self.handle(*args, **options)
  File "C:\Program Files (x86)\Python36\lib\site-packages\django\core\management\commands\loaddata.py", line 69, in handle
    self.loaddata(fixture_labels)
  File "C:\Program Files (x86)\Python36\lib\site-packages\django\core\management\commands\loaddata.py", line 102, in loaddata
    if self.find_fixtures(fixture_label):
  File "C:\Program Files (x86)\Python36\lib\site-packages\django\core\management\commands\loaddata.py", line 261, in find_fixtures
    raise CommandError("No fixture named '%s' found." % fixture_name)
django.core.management.base.CommandError: No fixture named 'authentication' found.
</error></testcase><testcase classname="unittest.suite._ErrorHolder" name="setUpClass (treasurer_tools.financial_codes.tests.test_views_financial_code_system.FinancialCodeSystemEditTest)" time="0.063112"><error message="No fixture named 'authentication' found." type="django.core.management.base.CommandError">Traceback (most recent call last):
  File "C:\Program Files (x86)\Python36\lib\site-packages\django\test\testcases.py", line 1036, in setUpClass
    'database': db_name,
  File "C:\Program Files (x86)\Python36\lib\site-packages\django\core\management\__init__.py", line 131, in call_command
    return command.execute(*args, **defaults)
  File "C:\Program Files (x86)\Python36\lib\site-packages\django\core\management\base.py", line 330, in execute
    output = self.handle(*args, **options)
  File "C:\Program Files (x86)\Python36\lib\site-packages\django\core\management\commands\loaddata.py", line 69, in handle
    self.loaddata(fixture_labels)
  File "C:\Program Files (x86)\Python36\lib\site-packages\django\core\management\commands\loaddata.py", line 102, in loaddata
    if self.find_fixtures(fixture_label):
  File "C:\Program Files (x86)\Python36\lib\site-packages\django\core\management\commands\loaddata.py", line 261, in find_fixtures
    raise CommandError("No fixture named '%s' found." % fixture_name)
django.core.management.base.CommandError: No fixture named 'authentication' found.
</error></testcase><testcase classname="unittest.suite._ErrorHolder" name="setUpClass (treasurer_tools.investments.tests.test_models.FinancialCodeSystemModelTest)" time="0.064114"><error message="No fixture named 'investment' found." type="django.core.management.base.CommandError">Traceback (most recent call last):
  File "C:\Program Files (x86)\Python36\lib\site-packages\django\test\testcases.py", line 1036, in setUpClass
    'database': db_name,
  File "C:\Program Files (x86)\Python36\lib\site-packages\django\core\management\__init__.py", line 131, in call_command
    return command.execute(*args, **defaults)
  File "C:\Program Files (x86)\Python36\lib\site-packages\django\core\management\base.py", line 330, in execute
    output = self.handle(*args, **options)
  File "C:\Program Files (x86)\Python36\lib\site-packages\django\core\management\commands\loaddata.py", line 69, in handle
    self.loaddata(fixture_labels)
  File "C:\Program Files (x86)\Python36\lib\site-packages\django\core\management\commands\loaddata.py", line 102, in loaddata
    if self.find_fixtures(fixture_label):
  File "C:\Program Files (x86)\Python36\lib\site-packages\django\core\management\commands\loaddata.py", line 261, in find_fixtures
    raise CommandError("No fixture named '%s' found." % fixture_name)
django.core.management.base.CommandError: No fixture named 'investment' found.
</error></testcase><testcase classname="unittest.suite._ErrorHolder" name="setUpClass (treasurer_tools.investments.tests.test_views.InvestmentAddTest)" time="0.065617"><error message="No fixture named 'authentication' found." type="django.core.management.base.CommandError">Traceback (most recent call last):
  File "C:\Program Files (x86)\Python36\lib\site-packages\django\test\testcases.py", line 1036, in setUpClass
    'database': db_name,
  File "C:\Program Files (x86)\Python36\lib\site-packages\django\core\management\__init__.py", line 131, in call_command
    return command.execute(*args, **defaults)
  File "C:\Program Files (x86)\Python36\lib\site-packages\django\core\management\base.py", line 330, in execute
    output = self.handle(*args, **options)
  File "C:\Program Files (x86)\Python36\lib\site-packages\django\core\management\commands\loaddata.py", line 69, in handle
    self.loaddata(fixture_labels)
  File "C:\Program Files (x86)\Python36\lib\site-packages\django\core\management\commands\loaddata.py", line 102, in loaddata
    if self.find_fixtures(fixture_label):
  File "C:\Program Files (x86)\Python36\lib\site-packages\django\core\management\commands\loaddata.py", line 261, in find_fixtures
    raise CommandError("No fixture named '%s' found." % fixture_name)
django.core.management.base.CommandError: No fixture named 'authentication' found.
</error></testcase><testcase classname="unittest.suite._ErrorHolder" name="setUpClass (treasurer_tools.investments.tests.test_views.InvestmentDeleteTest)" time="0.066619"><error message="No fixture named 'authentication' found." type="django.core.management.base.CommandError">Traceback (most recent call last):
  File "C:\Program Files (x86)\Python36\lib\site-packages\django\test\testcases.py", line 1036, in setUpClass
    'database': db_name,
  File "C:\Program Files (x86)\Python36\lib\site-packages\django\core\management\__init__.py", line 131, in call_command
    return command.execute(*args, **defaults)
  File "C:\Program Files (x86)\Python36\lib\site-packages\django\core\management\base.py", line 330, in execute
    output = self.handle(*args, **options)
  File "C:\Program Files (x86)\Python36\lib\site-packages\django\core\management\commands\loaddata.py", line 69, in handle
    self.loaddata(fixture_labels)
  File "C:\Program Files (x86)\Python36\lib\site-packages\django\core\management\commands\loaddata.py", line 102, in loaddata
    if self.find_fixtures(fixture_label):
  File "C:\Program Files (x86)\Python36\lib\site-packages\django\core\management\commands\loaddata.py", line 261, in find_fixtures
    raise CommandError("No fixture named '%s' found." % fixture_name)
django.core.management.base.CommandError: No fixture named 'authentication' found.
</error></testcase><testcase classname="unittest.suite._ErrorHolder" name="setUpClass (treasurer_tools.investments.tests.test_views.InvestmentEditTest)" time="0.068121"><error message="No fixture named 'authentication' found." type="django.core.management.base.CommandError">Traceback (most recent call last):
  File "C:\Program Files (x86)\Python36\lib\site-packages\django\test\testcases.py", line 1036, in setUpClass
    'database': db_name,
  File "C:\Program Files (x86)\Python36\lib\site-packages\django\core\management\__init__.py", line 131, in call_command
    return command.execute(*args, **defaults)
  File "C:\Program Files (x86)\Python36\lib\site-packages\django\core\management\base.py", line 330, in execute
    output = self.handle(*args, **options)
  File "C:\Program Files (x86)\Python36\lib\site-packages\django\core\management\commands\loaddata.py", line 69, in handle
    self.loaddata(fixture_labels)
  File "C:\Program Files (x86)\Python36\lib\site-packages\django\core\management\commands\loaddata.py", line 102, in loaddata
    if self.find_fixtures(fixture_label):
  File "C:\Program Files (x86)\Python36\lib\site-packages\django\core\management\commands\loaddata.py", line 261, in find_fixtures
    raise CommandError("No fixture named '%s' found." % fixture_name)
django.core.management.base.CommandError: No fixture named 'authentication' found.
</error></testcase><testcase classname="unittest.suite._ErrorHolder" name="setUpClass (treasurer_tools.investments.tests.test_views.InvestmentsDashboard)" time="0.069123"><error message="No fixture named 'authentication' found." type="django.core.management.base.CommandError">Traceback (most recent call last):
  File "C:\Program Files (x86)\Python36\lib\site-packages\django\test\testcases.py", line 1036, in setUpClass
    'database': db_name,
  File "C:\Program Files (x86)\Python36\lib\site-packages\django\core\management\__init__.py", line 131, in call_command
    return command.execute(*args, **defaults)
  File "C:\Program Files (x86)\Python36\lib\site-packages\django\core\management\base.py", line 330, in execute
    output = self.handle(*args, **options)
  File "C:\Program Files (x86)\Python36\lib\site-packages\django\core\management\commands\loaddata.py", line 69, in handle
    self.loaddata(fixture_labels)
  File "C:\Program Files (x86)\Python36\lib\site-packages\django\core\management\commands\loaddata.py", line 102, in loaddata
    if self.find_fixtures(fixture_label):
  File "C:\Program Files (x86)\Python36\lib\site-packages\django\core\management\commands\loaddata.py", line 261, in find_fixtures
    raise CommandError("No fixture named '%s' found." % fixture_name)
django.core.management.base.CommandError: No fixture named 'authentication' found.
</error></testcase><testcase classname="unittest.suite._ErrorHolder" name="setUpClass (treasurer_tools.payee_payer.tests.test_forms.CountryModelTest)" time="0.070626"><error message="No fixture named 'country' found." type="django.core.management.base.CommandError">Traceback (most recent call last):
  File "C:\Program Files (x86)\Python36\lib\site-packages\django\test\testcases.py", line 1036, in setUpClass
    'database': db_name,
  File "C:\Program Files (x86)\Python36\lib\site-packages\django\core\management\__init__.py", line 131, in call_command
    return command.execute(*args, **defaults)
  File "C:\Program Files (x86)\Python36\lib\site-packages\django\core\management\base.py", line 330, in execute
    output = self.handle(*args, **options)
  File "C:\Program Files (x86)\Python36\lib\site-packages\django\core\management\commands\loaddata.py", line 69, in handle
    self.loaddata(fixture_labels)
  File "C:\Program Files (x86)\Python36\lib\site-packages\django\core\management\commands\loaddata.py", line 102, in loaddata
    if self.find_fixtures(fixture_label):
  File "C:\Program Files (x86)\Python36\lib\site-packages\django\core\management\commands\loaddata.py", line 261, in find_fixtures
    raise CommandError("No fixture named '%s' found." % fixture_name)
django.core.management.base.CommandError: No fixture named 'country' found.
</error></testcase><testcase classname="unittest.suite._ErrorHolder" name="setUpClass (treasurer_tools.payee_payer.tests.test_models.CountryModelTest)" time="0.071627"><error message="No fixture named 'country' found." type="django.core.management.base.CommandError">Traceback (most recent call last):
  File "C:\Program Files (x86)\Python36\lib\site-packages\django\test\testcases.py", line 1036, in setUpClass
    'database': db_name,
  File "C:\Program Files (x86)\Python36\lib\site-packages\django\core\management\__init__.py", line 131, in call_command
    return command.execute(*args, **defaults)
  File "C:\Program Files (x86)\Python36\lib\site-packages\django\core\management\base.py", line 330, in execute
    output = self.handle(*args, **options)
  File "C:\Program Files (x86)\Python36\lib\site-packages\django\core\management\commands\loaddata.py", line 69, in handle
    self.loaddata(fixture_labels)
  File "C:\Program Files (x86)\Python36\lib\site-packages\django\core\management\commands\loaddata.py", line 102, in loaddata
    if self.find_fixtures(fixture_label):
  File "C:\Program Files (x86)\Python36\lib\site-packages\django\core\management\commands\loaddata.py", line 261, in find_fixtures
    raise CommandError("No fixture named '%s' found." % fixture_name)
django.core.management.base.CommandError: No fixture named 'country' found.
</error></testcase><testcase classname="unittest.suite._ErrorHolder" name="setUpClass (treasurer_tools.payee_payer.tests.test_models.DemographicsModelTest)" time="0.073130"><error message="No fixture named 'country' found." type="django.core.management.base.CommandError">Traceback (most recent call last):
  File "C:\Program Files (x86)\Python36\lib\site-packages\django\test\testcases.py", line 1036, in setUpClass
    'database': db_name,
  File "C:\Program Files (x86)\Python36\lib\site-packages\django\core\management\__init__.py", line 131, in call_command
    return command.execute(*args, **defaults)
  File "C:\Program Files (x86)\Python36\lib\site-packages\django\core\management\base.py", line 330, in execute
    output = self.handle(*args, **options)
  File "C:\Program Files (x86)\Python36\lib\site-packages\django\core\management\commands\loaddata.py", line 69, in handle
    self.loaddata(fixture_labels)
  File "C:\Program Files (x86)\Python36\lib\site-packages\django\core\management\commands\loaddata.py", line 102, in loaddata
    if self.find_fixtures(fixture_label):
  File "C:\Program Files (x86)\Python36\lib\site-packages\django\core\management\commands\loaddata.py", line 261, in find_fixtures
    raise CommandError("No fixture named '%s' found." % fixture_name)
django.core.management.base.CommandError: No fixture named 'country' found.
</error></testcase><testcase classname="unittest.suite._ErrorHolder" name="setUpClass (treasurer_tools.payee_payer.tests.test_views.DashboardTest)" time="0.074132"><error message="No fixture named 'authentication' found." type="django.core.management.base.CommandError">Traceback (most recent call last):
  File "C:\Program Files (x86)\Python36\lib\site-packages\django\test\testcases.py", line 1036, in setUpClass
    'database': db_name,
  File "C:\Program Files (x86)\Python36\lib\site-packages\django\core\management\__init__.py", line 131, in call_command
    return command.execute(*args, **defaults)
  File "C:\Program Files (x86)\Python36\lib\site-packages\django\core\management\base.py", line 330, in execute
    output = self.handle(*args, **options)
  File "C:\Program Files (x86)\Python36\lib\site-packages\django\core\management\commands\loaddata.py", line 69, in handle
    self.loaddata(fixture_labels)
  File "C:\Program Files (x86)\Python36\lib\site-packages\django\core\management\commands\loaddata.py", line 102, in loaddata
    if self.find_fixtures(fixture_label):
  File "C:\Program Files (x86)\Python36\lib\site-packages\django\core\management\commands\loaddata.py", line 261, in find_fixtures
    raise CommandError("No fixture named '%s' found." % fixture_name)
django.core.management.base.CommandError: No fixture named 'authentication' found.
</error></testcase><testcase classname="unittest.suite._ErrorHolder" name="setUpClass (treasurer_tools.payee_payer.tests.test_views.PayeePayerAddTest)" time="0.075634"><error message="No fixture named 'authentication' found." type="django.core.management.base.CommandError">Traceback (most recent call last):
  File "C:\Program Files (x86)\Python36\lib\site-packages\django\test\testcases.py", line 1036, in setUpClass
    'database': db_name,
  File "C:\Program Files (x86)\Python36\lib\site-packages\django\core\management\__init__.py", line 131, in call_command
    return command.execute(*args, **defaults)
  File "C:\Program Files (x86)\Python36\lib\site-packages\django\core\management\base.py", line 330, in execute
    output = self.handle(*args, **options)
  File "C:\Program Files (x86)\Python36\lib\site-packages\django\core\management\commands\loaddata.py", line 69, in handle
    self.loaddata(fixture_labels)
  File "C:\Program Files (x86)\Python36\lib\site-packages\django\core\management\commands\loaddata.py", line 102, in loaddata
    if self.find_fixtures(fixture_label):
  File "C:\Program Files (x86)\Python36\lib\site-packages\django\core\management\commands\loaddata.py", line 261, in find_fixtures
    raise CommandError("No fixture named '%s' found." % fixture_name)
django.core.management.base.CommandError: No fixture named 'authentication' found.
</error></testcase><testcase classname="unittest.suite._ErrorHolder" name="setUpClass (treasurer_tools.payee_payer.tests.test_views.PayeePayerDeleteTest)" time="0.076636"><error message="No fixture named 'authentication' found." type="django.core.management.base.CommandError">Traceback (most recent call last):
  File "C:\Program Files (x86)\Python36\lib\site-packages\django\test\testcases.py", line 1036, in setUpClass
    'database': db_name,
  File "C:\Program Files (x86)\Python36\lib\site-packages\django\core\management\__init__.py", line 131, in call_command
    return command.execute(*args, **defaults)
  File "C:\Program Files (x86)\Python36\lib\site-packages\django\core\management\base.py", line 330, in execute
    output = self.handle(*args, **options)
  File "C:\Program Files (x86)\Python36\lib\site-packages\django\core\management\commands\loaddata.py", line 69, in handle
    self.loaddata(fixture_labels)
  File "C:\Program Files (x86)\Python36\lib\site-packages\django\core\management\commands\loaddata.py", line 102, in loaddata
    if self.find_fixtures(fixture_label):
  File "C:\Program Files (x86)\Python36\lib\site-packages\django\core\management\commands\loaddata.py", line 261, in find_fixtures
    raise CommandError("No fixture named '%s' found." % fixture_name)
django.core.management.base.CommandError: No fixture named 'authentication' found.
</error></testcase><testcase classname="unittest.suite._ErrorHolder" name="setUpClass (treasurer_tools.payee_payer.tests.test_views.PayeePayerEditTest)" time="0.078139"><error message="No fixture named 'authentication' found." type="django.core.management.base.CommandError">Traceback (most recent call last):
  File "C:\Program Files (x86)\Python36\lib\site-packages\django\test\testcases.py", line 1036, in setUpClass
    'database': db_name,
  File "C:\Program Files (x86)\Python36\lib\site-packages\django\core\management\__init__.py", line 131, in call_command
    return command.execute(*args, **defaults)
  File "C:\Program Files (x86)\Python36\lib\site-packages\django\core\management\base.py", line 330, in execute
    output = self.handle(*args, **options)
  File "C:\Program Files (x86)\Python36\lib\site-packages\django\core\management\commands\loaddata.py", line 69, in handle
    self.loaddata(fixture_labels)
  File "C:\Program Files (x86)\Python36\lib\site-packages\django\core\management\commands\loaddata.py", line 102, in loaddata
    if self.find_fixtures(fixture_label):
  File "C:\Program Files (x86)\Python36\lib\site-packages\django\core\management\commands\loaddata.py", line 261, in find_fixtures
    raise CommandError("No fixture named '%s' found." % fixture_name)
django.core.management.base.CommandError: No fixture named 'authentication' found.
</error></testcase><testcase classname="unittest.suite._ErrorHolder" name="setUpClass (treasurer_tools.payee_payer.tests.test_views.RetrieveListTest)" time="0.079141"><error message="No fixture named 'authentication' found." type="django.core.management.base.CommandError">Traceback (most recent call last):
  File "C:\Program Files (x86)\Python36\lib\site-packages\django\test\testcases.py", line 1036, in setUpClass
    'database': db_name,
  File "C:\Program Files (x86)\Python36\lib\site-packages\django\core\management\__init__.py", line 131, in call_command
    return command.execute(*args, **defaults)
  File "C:\Program Files (x86)\Python36\lib\site-packages\django\core\management\base.py", line 330, in execute
    output = self.handle(*args, **options)
  File "C:\Program Files (x86)\Python36\lib\site-packages\django\core\management\commands\loaddata.py", line 69, in handle
    self.loaddata(fixture_labels)
  File "C:\Program Files (x86)\Python36\lib\site-packages\django\core\management\commands\loaddata.py", line 102, in loaddata
    if self.find_fixtures(fixture_label):
  File "C:\Program Files (x86)\Python36\lib\site-packages\django\core\management\commands\loaddata.py", line 261, in find_fixtures
    raise CommandError("No fixture named '%s' found." % fixture_name)
django.core.management.base.CommandError: No fixture named 'authentication' found.
</error></testcase><testcase classname="unittest.suite._ErrorHolder" name="setUpClass (treasurer_tools.transactions.tests.test_forms.CompiledFormsTest)" time="0.080643"><error message="No fixture named 'authentication' found." type="django.core.management.base.CommandError">Traceback (most recent call last):
  File "C:\Program Files (x86)\Python36\lib\site-packages\django\test\testcases.py", line 1036, in setUpClass
    'database': db_name,
  File "C:\Program Files (x86)\Python36\lib\site-packages\django\core\management\__init__.py", line 131, in call_command
    return command.execute(*args, **defaults)
  File "C:\Program Files (x86)\Python36\lib\site-packages\django\core\management\base.py", line 330, in execute
    output = self.handle(*args, **options)
  File "C:\Program Files (x86)\Python36\lib\site-packages\django\core\management\commands\loaddata.py", line 69, in handle
    self.loaddata(fixture_labels)
  File "C:\Program Files (x86)\Python36\lib\site-packages\django\core\management\commands\loaddata.py", line 102, in loaddata
    if self.find_fixtures(fixture_label):
  File "C:\Program Files (x86)\Python36\lib\site-packages\django\core\management\commands\loaddata.py", line 261, in find_fixtures
    raise CommandError("No fixture named '%s' found." % fixture_name)
django.core.management.base.CommandError: No fixture named 'authentication' found.
</error></testcase><testcase classname="unittest.suite._ErrorHolder" name="setUpClass (treasurer_tools.transactions.tests.test_forms.FinancialCodeAssignmentFormTest)" time="0.082146"><error message="No fixture named 'financial_code_system' found." type="django.core.management.base.CommandError">Traceback (most recent call last):
  File "C:\Program Files (x86)\Python36\lib\site-packages\django\test\testcases.py", line 1036, in setUpClass
    'database': db_name,
  File "C:\Program Files (x86)\Python36\lib\site-packages\django\core\management\__init__.py", line 131, in call_command
    return command.execute(*args, **defaults)
  File "C:\Program Files (x86)\Python36\lib\site-packages\django\core\management\base.py", line 330, in execute
    output = self.handle(*args, **options)
  File "C:\Program Files (x86)\Python36\lib\site-packages\django\core\management\commands\loaddata.py", line 69, in handle
    self.loaddata(fixture_labels)
  File "C:\Program Files (x86)\Python36\lib\site-packages\django\core\management\commands\loaddata.py", line 102, in loaddata
    if self.find_fixtures(fixture_label):
  File "C:\Program Files (x86)\Python36\lib\site-packages\django\core\management\commands\loaddata.py", line 261, in find_fixtures
    raise CommandError("No fixture named '%s' found." % fixture_name)
django.core.management.base.CommandError: No fixture named 'financial_code_system' found.
</error></testcase><testcase classname="unittest.suite._ErrorHolder" name="setUpClass (treasurer_tools.transactions.tests.test_models.AttachmentMatchModelTest)" time="0.083148"><error message="No fixture named 'country' found." type="django.core.management.base.CommandError">Traceback (most recent call last):
  File "C:\Program Files (x86)\Python36\lib\site-packages\django\test\testcases.py", line 1036, in setUpClass
    'database': db_name,
  File "C:\Program Files (x86)\Python36\lib\site-packages\django\core\management\__init__.py", line 131, in call_command
    return command.execute(*args, **defaults)
  File "C:\Program Files (x86)\Python36\lib\site-packages\django\core\management\base.py", line 330, in execute
    output = self.handle(*args, **options)
  File "C:\Program Files (x86)\Python36\lib\site-packages\django\core\management\commands\loaddata.py", line 69, in handle
    self.loaddata(fixture_labels)
  File "C:\Program Files (x86)\Python36\lib\site-packages\django\core\management\commands\loaddata.py", line 102, in loaddata
    if self.find_fixtures(fixture_label):
  File "C:\Program Files (x86)\Python36\lib\site-packages\django\core\management\commands\loaddata.py", line 261, in find_fixtures
    raise CommandError("No fixture named '%s' found." % fixture_name)
django.core.management.base.CommandError: No fixture named 'country' found.
</error></testcase><testcase classname="unittest.suite._ErrorHolder" name="setUpClass (treasurer_tools.transactions.tests.test_models.FinancialCodeMatchModelTest)" time="0.084650"><error message="No fixture named 'country' found." type="django.core.management.base.CommandError">Traceback (most recent call last):
  File "C:\Program Files (x86)\Python36\lib\site-packages\django\test\testcases.py", line 1036, in setUpClass
    'database': db_name,
  File "C:\Program Files (x86)\Python36\lib\site-packages\django\core\management\__init__.py", line 131, in call_command
    return command.execute(*args, **defaults)
  File "C:\Program Files (x86)\Python36\lib\site-packages\django\core\management\base.py", line 330, in execute
    output = self.handle(*args, **options)
  File "C:\Program Files (x86)\Python36\lib\site-packages\django\core\management\commands\loaddata.py", line 69, in handle
    self.loaddata(fixture_labels)
  File "C:\Program Files (x86)\Python36\lib\site-packages\django\core\management\commands\loaddata.py", line 102, in loaddata
    if self.find_fixtures(fixture_label):
  File "C:\Program Files (x86)\Python36\lib\site-packages\django\core\management\commands\loaddata.py", line 261, in find_fixtures
    raise CommandError("No fixture named '%s' found." % fixture_name)
django.core.management.base.CommandError: No fixture named 'country' found.
</error></testcase><testcase classname="unittest.suite._ErrorHolder" name="setUpClass (treasurer_tools.transactions.tests.test_models.ItemModelTest)" time="0.085652"><error message="No fixture named 'country' found." type="django.core.management.base.CommandError">Traceback (most recent call last):
  File "C:\Program Files (x86)\Python36\lib\site-packages\django\test\testcases.py", line 1036, in setUpClass
    'database': db_name,
  File "C:\Program Files (x86)\Python36\lib\site-packages\django\core\management\__init__.py", line 131, in call_command
    return command.execute(*args, **defaults)
  File "C:\Program Files (x86)\Python36\lib\site-packages\django\core\management\base.py", line 330, in execute
    output = self.handle(*args, **options)
  File "C:\Program Files (x86)\Python36\lib\site-packages\django\core\management\commands\loaddata.py", line 69, in handle
    self.loaddata(fixture_labels)
  File "C:\Program Files (x86)\Python36\lib\site-packages\django\core\management\commands\loaddata.py", line 102, in loaddata
    if self.find_fixtures(fixture_label):
  File "C:\Program Files (x86)\Python36\lib\site-packages\django\core\management\commands\loaddata.py", line 261, in find_fixtures
    raise CommandError("No fixture named '%s' found." % fixture_name)
django.core.management.base.CommandError: No fixture named 'country' found.
</error></testcase><testcase classname="unittest.suite._ErrorHolder" name="setUpClass (treasurer_tools.transactions.tests.test_models.TransactionModelTest)" time="0.087155"><error message="No fixture named 'country' found." type="django.core.management.base.CommandError">Traceback (most recent call last):
  File "C:\Program Files (x86)\Python36\lib\site-packages\django\test\testcases.py", line 1036, in setUpClass
    'database': db_name,
  File "C:\Program Files (x86)\Python36\lib\site-packages\django\core\management\__init__.py", line 131, in call_command
    return command.execute(*args, **defaults)
  File "C:\Program Files (x86)\Python36\lib\site-packages\django\core\management\base.py", line 330, in execute
    output = self.handle(*args, **options)
  File "C:\Program Files (x86)\Python36\lib\site-packages\django\core\management\commands\loaddata.py", line 69, in handle
    self.loaddata(fixture_labels)
  File "C:\Program Files (x86)\Python36\lib\site-packages\django\core\management\commands\loaddata.py", line 102, in loaddata
    if self.find_fixtures(fixture_label):
  File "C:\Program Files (x86)\Python36\lib\site-packages\django\core\management\commands\loaddata.py", line 261, in find_fixtures
    raise CommandError("No fixture named '%s' found." % fixture_name)
django.core.management.base.CommandError: No fixture named 'country' found.
</error></testcase><testcase classname="unittest.suite._ErrorHolder" name="setUpClass (treasurer_tools.transactions.tests.test_views_add.ExpenseAddTest)" time="0.088157"><error message="No fixture named 'authentication' found." type="django.core.management.base.CommandError">Traceback (most recent call last):
  File "C:\Program Files (x86)\Python36\lib\site-packages\django\test\testcases.py", line 1036, in setUpClass
    'database': db_name,
  File "C:\Program Files (x86)\Python36\lib\site-packages\django\core\management\__init__.py", line 131, in call_command
    return command.execute(*args, **defaults)
  File "C:\Program Files (x86)\Python36\lib\site-packages\django\core\management\base.py", line 330, in execute
    output = self.handle(*args, **options)
  File "C:\Program Files (x86)\Python36\lib\site-packages\django\core\management\commands\loaddata.py", line 69, in handle
    self.loaddata(fixture_labels)
  File "C:\Program Files (x86)\Python36\lib\site-packages\django\core\management\commands\loaddata.py", line 102, in loaddata
    if self.find_fixtures(fixture_label):
  File "C:\Program Files (x86)\Python36\lib\site-packages\django\core\management\commands\loaddata.py", line 261, in find_fixtures
    raise CommandError("No fixture named '%s' found." % fixture_name)
django.core.management.base.CommandError: No fixture named 'authentication' found.
</error></testcase><testcase classname="unittest.suite._ErrorHolder" name="setUpClass (treasurer_tools.transactions.tests.test_views_add.RevenueAddTest)" time="0.089659"><error message="No fixture named 'authentication' found." type="django.core.management.base.CommandError">Traceback (most recent call last):
  File "C:\Program Files (x86)\Python36\lib\site-packages\django\test\testcases.py", line 1036, in setUpClass
    'database': db_name,
  File "C:\Program Files (x86)\Python36\lib\site-packages\django\core\management\__init__.py", line 131, in call_command
    return command.execute(*args, **defaults)
  File "C:\Program Files (x86)\Python36\lib\site-packages\django\core\management\base.py", line 330, in execute
    output = self.handle(*args, **options)
  File "C:\Program Files (x86)\Python36\lib\site-packages\django\core\management\commands\loaddata.py", line 69, in handle
    self.loaddata(fixture_labels)
  File "C:\Program Files (x86)\Python36\lib\site-packages\django\core\management\commands\loaddata.py", line 102, in loaddata
    if self.find_fixtures(fixture_label):
  File "C:\Program Files (x86)\Python36\lib\site-packages\django\core\management\commands\loaddata.py", line 261, in find_fixtures
    raise CommandError("No fixture named '%s' found." % fixture_name)
django.core.management.base.CommandError: No fixture named 'authentication' found.
</error></testcase><testcase classname="treasurer_tools.transactions.tests.test_views_add.TransactionAddTest" name="test_transaction_add_html404_on_invalid_name" time="0.018032" /><testcase classname="treasurer_tools.transactions.tests.test_views_add.TransactionAddTest" name="test_transaction_add_html404_on_invalid_url" time="0.082146" /><testcase classname="unittest.suite._ErrorHolder" name="setUpClass (treasurer_tools.transactions.tests.test_views_delete.ExpenseDeleteTest)" time="0.107691"><error message="No fixture named 'authentication' found." type="django.core.management.base.CommandError">Traceback (most recent call last):
  File "C:\Program Files (x86)\Python36\lib\site-packages\django\test\testcases.py", line 1036, in setUpClass
    'database': db_name,
  File "C:\Program Files (x86)\Python36\lib\site-packages\django\core\management\__init__.py", line 131, in call_command
    return command.execute(*args, **defaults)
  File "C:\Program Files (x86)\Python36\lib\site-packages\django\core\management\base.py", line 330, in execute
    output = self.handle(*args, **options)
  File "C:\Program Files (x86)\Python36\lib\site-packages\django\core\management\commands\loaddata.py", line 69, in handle
    self.loaddata(fixture_labels)
  File "C:\Program Files (x86)\Python36\lib\site-packages\django\core\management\commands\loaddata.py", line 102, in loaddata
    if self.find_fixtures(fixture_label):
  File "C:\Program Files (x86)\Python36\lib\site-packages\django\core\management\commands\loaddata.py", line 261, in find_fixtures
    raise CommandError("No fixture named '%s' found." % fixture_name)
django.core.management.base.CommandError: No fixture named 'authentication' found.
</error></testcase><testcase classname="unittest.suite._ErrorHolder" name="setUpClass (treasurer_tools.transactions.tests.test_views_delete.RevenueDeleteTest)" time="0.109694"><error message="No fixture named 'authentication' found." type="django.core.management.base.CommandError">Traceback (most recent call last):
  File "C:\Program Files (x86)\Python36\lib\site-packages\django\test\testcases.py", line 1036, in setUpClass
    'database': db_name,
  File "C:\Program Files (x86)\Python36\lib\site-packages\django\core\management\__init__.py", line 131, in call_command
    return command.execute(*args, **defaults)
  File "C:\Program Files (x86)\Python36\lib\site-packages\django\core\management\base.py", line 330, in execute
    output = self.handle(*args, **options)
  File "C:\Program Files (x86)\Python36\lib\site-packages\django\core\management\commands\loaddata.py", line 69, in handle
    self.loaddata(fixture_labels)
  File "C:\Program Files (x86)\Python36\lib\site-packages\django\core\management\commands\loaddata.py", line 102, in loaddata
    if self.find_fixtures(fixture_label):
  File "C:\Program Files (x86)\Python36\lib\site-packages\django\core\management\commands\loaddata.py", line 261, in find_fixtures
    raise CommandError("No fixture named '%s' found." % fixture_name)
django.core.management.base.CommandError: No fixture named 'authentication' found.
</error></testcase><testcase classname="unittest.suite._ErrorHolder" name="setUpClass (treasurer_tools.transactions.tests.test_views_delete.TransactionDeleteTest)" time="0.110696"><error message="No fixture named 'authentication' found." type="django.core.management.base.CommandError">Traceback (most recent call last):
  File "C:\Program Files (x86)\Python36\lib\site-packages\django\test\testcases.py", line 1036, in setUpClass
    'database': db_name,
  File "C:\Program Files (x86)\Python36\lib\site-packages\django\core\management\__init__.py", line 131, in call_command
    return command.execute(*args, **defaults)
  File "C:\Program Files (x86)\Python36\lib\site-packages\django\core\management\base.py", line 330, in execute
    output = self.handle(*args, **options)
  File "C:\Program Files (x86)\Python36\lib\site-packages\django\core\management\commands\loaddata.py", line 69, in handle
    self.loaddata(fixture_labels)
  File "C:\Program Files (x86)\Python36\lib\site-packages\django\core\management\commands\loaddata.py", line 102, in loaddata
    if self.find_fixtures(fixture_label):
  File "C:\Program Files (x86)\Python36\lib\site-packages\django\core\management\commands\loaddata.py", line 261, in find_fixtures
    raise CommandError("No fixture named '%s' found." % fixture_name)
django.core.management.base.CommandError: No fixture named 'authentication' found.
</error></testcase><testcase classname="unittest.suite._ErrorHolder" name="setUpClass (treasurer_tools.transactions.tests.test_views_edit.ExpenseEditTest)" time="0.112199"><error message="No fixture named 'authentication' found." type="django.core.management.base.CommandError">Traceback (most recent call last):
  File "C:\Program Files (x86)\Python36\lib\site-packages\django\test\testcases.py", line 1036, in setUpClass
    'database': db_name,
  File "C:\Program Files (x86)\Python36\lib\site-packages\django\core\management\__init__.py", line 131, in call_command
    return command.execute(*args, **defaults)
  File "C:\Program Files (x86)\Python36\lib\site-packages\django\core\management\base.py", line 330, in execute
    output = self.handle(*args, **options)
  File "C:\Program Files (x86)\Python36\lib\site-packages\django\core\management\commands\loaddata.py", line 69, in handle
    self.loaddata(fixture_labels)
  File "C:\Program Files (x86)\Python36\lib\site-packages\django\core\management\commands\loaddata.py", line 102, in loaddata
    if self.find_fixtures(fixture_label):
  File "C:\Program Files (x86)\Python36\lib\site-packages\django\core\management\commands\loaddata.py", line 261, in find_fixtures
    raise CommandError("No fixture named '%s' found." % fixture_name)
django.core.management.base.CommandError: No fixture named 'authentication' found.
</error></testcase><testcase classname="unittest.suite._ErrorHolder" name="setUpClass (treasurer_tools.transactions.tests.test_views_edit.RevenueEditTest)" time="0.113200"><error message="No fixture named 'authentication' found." type="django.core.management.base.CommandError">Traceback (most recent call last):
  File "C:\Program Files (x86)\Python36\lib\site-packages\django\test\testcases.py", line 1036, in setUpClass
    'database': db_name,
  File "C:\Program Files (x86)\Python36\lib\site-packages\django\core\management\__init__.py", line 131, in call_command
    return command.execute(*args, **defaults)
  File "C:\Program Files (x86)\Python36\lib\site-packages\django\core\management\base.py", line 330, in execute
    output = self.handle(*args, **options)
  File "C:\Program Files (x86)\Python36\lib\site-packages\django\core\management\commands\loaddata.py", line 69, in handle
    self.loaddata(fixture_labels)
  File "C:\Program Files (x86)\Python36\lib\site-packages\django\core\management\commands\loaddata.py", line 102, in loaddata
    if self.find_fixtures(fixture_label):
  File "C:\Program Files (x86)\Python36\lib\site-packages\django\core\management\commands\loaddata.py", line 261, in find_fixtures
    raise CommandError("No fixture named '%s' found." % fixture_name)
django.core.management.base.CommandError: No fixture named 'authentication' found.
</error></testcase><testcase classname="unittest.suite._ErrorHolder" name="setUpClass (treasurer_tools.transactions.tests.test_views_edit.TransactionEditTest)" time="0.114703"><error message="No fixture named 'authentication' found." type="django.core.management.base.CommandError">Traceback (most recent call last):
  File "C:\Program Files (x86)\Python36\lib\site-packages\django\test\testcases.py", line 1036, in setUpClass
    'database': db_name,
  File "C:\Program Files (x86)\Python36\lib\site-packages\django\core\management\__init__.py", line 131, in call_command
    return command.execute(*args, **defaults)
  File "C:\Program Files (x86)\Python36\lib\site-packages\django\core\management\base.py", line 330, in execute
    output = self.handle(*args, **options)
  File "C:\Program Files (x86)\Python36\lib\site-packages\django\core\management\commands\loaddata.py", line 69, in handle
    self.loaddata(fixture_labels)
  File "C:\Program Files (x86)\Python36\lib\site-packages\django\core\management\commands\loaddata.py", line 102, in loaddata
    if self.find_fixtures(fixture_label):
  File "C:\Program Files (x86)\Python36\lib\site-packages\django\core\management\commands\loaddata.py", line 261, in find_fixtures
    raise CommandError("No fixture named '%s' found." % fixture_name)
django.core.management.base.CommandError: No fixture named 'authentication' found.
</error></testcase><testcase classname="unittest.loader._FailedTest" name="treasurer_tools.bank_reconciliation.tests.test_models" time="0.000000"><error message="Failed to import test module: treasurer_tools.bank_reconciliation.tests.test_models&#10;Traceback (most recent call last):&#10;  File &quot;C:\Program Files (x86)\Python36\lib\unittest\loader.py&quot;, line 428, in _find_test_path&#10;    module = self._get_module_from_name(name)&#10;  File &quot;C:\Program Files (x86)\Python36\lib\unittest\loader.py&quot;, line 369, in _get_module_from_name&#10;    __import__(name)&#10;  File &quot;E:\My Documents\GitHub\treasurer_tools\treasurer_tools\bank_reconciliation\tests\test_models.py&quot;, line 5, in &lt;module&gt;&#10;    from ..models import ReconciliationMatch&#10;  File &quot;E:\My Documents\GitHub\treasurer_tools\treasurer_tools\bank_reconciliation\models.py&quot;, line 9, in &lt;module&gt;&#10;    class ReconciliationMatch(models.Model):&#10;  File &quot;C:\Program Files (x86)\Python36\lib\site-packages\django\db\models\base.py&quot;, line 118, in __new__&#10;    &quot;INSTALLED_APPS.&quot; % (module, name)&#10;RuntimeError: Model class treasurer_tools.bank_reconciliation.models.ReconciliationMatch doesn't declare an explicit app_label and isn't in an application in INSTALLED_APPS.&#10;" type="builtins.ImportError">ImportError: Failed to import test module: treasurer_tools.bank_reconciliation.tests.test_models
Traceback (most recent call last):
  File "C:\Program Files (x86)\Python36\lib\unittest\loader.py", line 428, in _find_test_path
    module = self._get_module_from_name(name)
  File "C:\Program Files (x86)\Python36\lib\unittest\loader.py", line 369, in _get_module_from_name
    __import__(name)
  File "E:\My Documents\GitHub\treasurer_tools\treasurer_tools\bank_reconciliation\tests\test_models.py", line 5, in &lt;module&gt;
    from ..models import ReconciliationMatch
  File "E:\My Documents\GitHub\treasurer_tools\treasurer_tools\bank_reconciliation\models.py", line 9, in &lt;module&gt;
    class ReconciliationMatch(models.Model):
  File "C:\Program Files (x86)\Python36\lib\site-packages\django\db\models\base.py", line 118, in __new__
    "INSTALLED_APPS." % (module, name)
RuntimeError: Model class treasurer_tools.bank_reconciliation.models.ReconciliationMatch doesn't declare an explicit app_label and isn't in an application in INSTALLED_APPS.

</error></testcase><testcase classname="unittest.loader._FailedTest" name="treasurer_tools.bank_reconciliation.tests.test_utils" time="0.000000"><error message="Failed to import test module: treasurer_tools.bank_reconciliation.tests.test_utils&#10;Traceback (most recent call last):&#10;  File &quot;C:\Program Files (x86)\Python36\lib\unittest\loader.py&quot;, line 428, in _find_test_path&#10;    module = self._get_module_from_name(name)&#10;  File &quot;C:\Program Files (x86)\Python36\lib\unittest\loader.py&quot;, line 369, in _get_module_from_name&#10;    __import__(name)&#10;  File &quot;E:\My Documents\GitHub\treasurer_tools\treasurer_tools\bank_reconciliation\tests\test_utils.py&quot;, line 8, in &lt;module&gt;&#10;    from ..models import ReconciliationMatch&#10;  File &quot;E:\My Documents\GitHub\treasurer_tools\treasurer_tools\bank_reconciliation\models.py&quot;, line 9, in &lt;module&gt;&#10;    class ReconciliationMatch(models.Model):&#10;  File &quot;C:\Program Files (x86)\Python36\lib\site-packages\django\db\models\base.py&quot;, line 118, in __new__&#10;    &quot;INSTALLED_APPS.&quot; % (module, name)&#10;RuntimeError: Model class treasurer_tools.bank_reconciliation.models.ReconciliationMatch doesn't declare an explicit app_label and isn't in an application in INSTALLED_APPS.&#10;" type="builtins.ImportError">ImportError: Failed to import test module: treasurer_tools.bank_reconciliation.tests.test_utils
Traceback (most recent call last):
  File "C:\Program Files (x86)\Python36\lib\unittest\loader.py", line 428, in _find_test_path
    module = self._get_module_from_name(name)
  File "C:\Program Files (x86)\Python36\lib\unittest\loader.py", line 369, in _get_module_from_name
    __import__(name)
  File "E:\My Documents\GitHub\treasurer_tools\treasurer_tools\bank_reconciliation\tests\test_utils.py", line 8, in &lt;module&gt;
    from ..models import ReconciliationMatch
  File "E:\My Documents\GitHub\treasurer_tools\treasurer_tools\bank_reconciliation\models.py", line 9, in &lt;module&gt;
    class ReconciliationMatch(models.Model):
  File "C:\Program Files (x86)\Python36\lib\site-packages\django\db\models\base.py", line 118, in __new__
    "INSTALLED_APPS." % (module, name)
RuntimeError: Model class treasurer_tools.bank_reconciliation.models.ReconciliationMatch doesn't declare an explicit app_label and isn't in an application in INSTALLED_APPS.

</error></testcase><testcase classname="unittest.loader._FailedTest" name="treasurer_tools.bank_reconciliation.tests.test_views" time="0.000000"><error message="Failed to import test module: treasurer_tools.bank_reconciliation.tests.test_views&#10;Traceback (most recent call last):&#10;  File &quot;C:\Program Files (x86)\Python36\lib\unittest\loader.py&quot;, line 428, in _find_test_path&#10;    module = self._get_module_from_name(name)&#10;  File &quot;C:\Program Files (x86)\Python36\lib\unittest\loader.py&quot;, line 369, in _get_module_from_name&#10;    __import__(name)&#10;  File &quot;E:\My Documents\GitHub\treasurer_tools\treasurer_tools\bank_reconciliation\tests\test_views.py&quot;, line 12, in &lt;module&gt;&#10;    from ..models import ReconciliationMatch&#10;  File &quot;E:\My Documents\GitHub\treasurer_tools\treasurer_tools\bank_reconciliation\models.py&quot;, line 9, in &lt;module&gt;&#10;    class ReconciliationMatch(models.Model):&#10;  File &quot;C:\Program Files (x86)\Python36\lib\site-packages\django\db\models\base.py&quot;, line 118, in __new__&#10;    &quot;INSTALLED_APPS.&quot; % (module, name)&#10;RuntimeError: Model class treasurer_tools.bank_reconciliation.models.ReconciliationMatch doesn't declare an explicit app_label and isn't in an application in INSTALLED_APPS.&#10;" type="builtins.ImportError">ImportError: Failed to import test module: treasurer_tools.bank_reconciliation.tests.test_views
Traceback (most recent call last):
  File "C:\Program Files (x86)\Python36\lib\unittest\loader.py", line 428, in _find_test_path
    module = self._get_module_from_name(name)
  File "C:\Program Files (x86)\Python36\lib\unittest\loader.py", line 369, in _get_module_from_name
    __import__(name)
  File "E:\My Documents\GitHub\treasurer_tools\treasurer_tools\bank_reconciliation\tests\test_views.py", line 12, in &lt;module&gt;
    from ..models import ReconciliationMatch
  File "E:\My Documents\GitHub\treasurer_tools\treasurer_tools\bank_reconciliation\models.py", line 9, in &lt;module&gt;
    class ReconciliationMatch(models.Model):
  File "C:\Program Files (x86)\Python36\lib\site-packages\django\db\models\base.py", line 118, in __new__
    "INSTALLED_APPS." % (module, name)
RuntimeError: Model class treasurer_tools.bank_reconciliation.models.ReconciliationMatch doesn't declare an explicit app_label and isn't in an application in INSTALLED_APPS.

</error></testcase><testcase classname="unittest.loader._FailedTest" name="treasurer_tools.financial_codes.tests.test_forms" time="0.000000"><error message="Failed to import test module: treasurer_tools.financial_codes.tests.test_forms&#10;Traceback (most recent call last):&#10;  File &quot;C:\Program Files (x86)\Python36\lib\unittest\loader.py&quot;, line 428, in _find_test_path&#10;    module = self._get_module_from_name(name)&#10;  File &quot;C:\Program Files (x86)\Python36\lib\unittest\loader.py&quot;, line 369, in _get_module_from_name&#10;    __import__(name)&#10;  File &quot;E:\My Documents\GitHub\treasurer_tools\treasurer_tools\financial_codes\tests\test_forms.py&quot;, line 5, in &lt;module&gt;&#10;    from ..forms import FinancialCodeSystemForm, BudgetYearForm, FinancialCodeForm&#10;  File &quot;E:\My Documents\GitHub\treasurer_tools\treasurer_tools\financial_codes\forms.py&quot;, line 6, in &lt;module&gt;&#10;    from .models import (&#10;  File &quot;E:\My Documents\GitHub\treasurer_tools\treasurer_tools\financial_codes\models.py&quot;, line 7, in &lt;module&gt;&#10;    class FinancialCodeSystem(models.Model):&#10;  File &quot;C:\Program Files (x86)\Python36\lib\site-packages\django\db\models\base.py&quot;, line 118, in __new__&#10;    &quot;INSTALLED_APPS.&quot; % (module, name)&#10;RuntimeError: Model class treasurer_tools.financial_codes.models.FinancialCodeSystem doesn't declare an explicit app_label and isn't in an application in INSTALLED_APPS.&#10;" type="builtins.ImportError">ImportError: Failed to import test module: treasurer_tools.financial_codes.tests.test_forms
Traceback (most recent call last):
  File "C:\Program Files (x86)\Python36\lib\unittest\loader.py", line 428, in _find_test_path
    module = self._get_module_from_name(name)
  File "C:\Program Files (x86)\Python36\lib\unittest\loader.py", line 369, in _get_module_from_name
    __import__(name)
  File "E:\My Documents\GitHub\treasurer_tools\treasurer_tools\financial_codes\tests\test_forms.py", line 5, in &lt;module&gt;
    from ..forms import FinancialCodeSystemForm, BudgetYearForm, FinancialCodeForm
  File "E:\My Documents\GitHub\treasurer_tools\treasurer_tools\financial_codes\forms.py", line 6, in &lt;module&gt;
    from .models import (
  File "E:\My Documents\GitHub\treasurer_tools\treasurer_tools\financial_codes\models.py", line 7, in &lt;module&gt;
    class FinancialCodeSystem(models.Model):
  File "C:\Program Files (x86)\Python36\lib\site-packages\django\db\models\base.py", line 118, in __new__
    "INSTALLED_APPS." % (module, name)
RuntimeError: Model class treasurer_tools.financial_codes.models.FinancialCodeSystem doesn't declare an explicit app_label and isn't in an application in INSTALLED_APPS.

</error></testcase><testcase classname="unittest.loader._FailedTest" name="treasurer_tools.transactions.tests.test_views_other" time="0.000000"><error message="Failed to import test module: treasurer_tools.transactions.tests.test_views_other&#10;Traceback (most recent call last):&#10;  File &quot;C:\Program Files (x86)\Python36\lib\unittest\loader.py&quot;, line 428, in _find_test_path&#10;    module = self._get_module_from_name(name)&#10;  File &quot;C:\Program Files (x86)\Python36\lib\unittest\loader.py&quot;, line 369, in _get_module_from_name&#10;    __import__(name)&#10;  File &quot;E:\My Documents\GitHub\treasurer_tools\treasurer_tools\transactions\tests\test_views_other.py&quot;, line 6, in &lt;module&gt;&#10;    from ..forms import FinancialCodeAssignmentForm&#10;  File &quot;E:\My Documents\GitHub\treasurer_tools\treasurer_tools\transactions\forms.py&quot;, line 15, in &lt;module&gt;&#10;    from .models import Transaction, Item, FinancialCodeMatch, AttachmentMatch&#10;  File &quot;E:\My Documents\GitHub\treasurer_tools\treasurer_tools\transactions\models.py&quot;, line 12, in &lt;module&gt;&#10;    class Transaction(models.Model):&#10;  File &quot;C:\Program Files (x86)\Python36\lib\site-packages\django\db\models\base.py&quot;, line 118, in __new__&#10;    &quot;INSTALLED_APPS.&quot; % (module, name)&#10;RuntimeError: Model class treasurer_tools.transactions.models.Transaction doesn't declare an explicit app_label and isn't in an application in INSTALLED_APPS.&#10;" type="builtins.ImportError">ImportError: Failed to import test module: treasurer_tools.transactions.tests.test_views_other
Traceback (most recent call last):
  File "C:\Program Files (x86)\Python36\lib\unittest\loader.py", line 428, in _find_test_path
    module = self._get_module_from_name(name)
  File "C:\Program Files (x86)\Python36\lib\unittest\loader.py", line 369, in _get_module_from_name
    __import__(name)
  File "E:\My Documents\GitHub\treasurer_tools\treasurer_tools\transactions\tests\test_views_other.py", line 6, in &lt;module&gt;
    from ..forms import FinancialCodeAssignmentForm
  File "E:\My Documents\GitHub\treasurer_tools\treasurer_tools\transactions\forms.py", line 15, in &lt;module&gt;
    from .models import Transaction, Item, FinancialCodeMatch, AttachmentMatch
  File "E:\My Documents\GitHub\treasurer_tools\treasurer_tools\transactions\models.py", line 12, in &lt;module&gt;
    class Transaction(models.Model):
  File "C:\Program Files (x86)\Python36\lib\site-packages\django\db\models\base.py", line 118, in __new__
    "INSTALLED_APPS." % (module, name)
RuntimeError: Model class treasurer_tools.transactions.models.Transaction doesn't declare an explicit app_label and isn't in an application in INSTALLED_APPS.

</error></testcase></testsuite>